Traceback (most recent call last):
  File "C:\Users\udayp\DatabaseStoreManager\manage.py", line 22, in <module>
    main()
    ~~~~^^
  File "C:\Users\udayp\DatabaseStoreManager\manage.py", line 18, in main
    execute_from_command_line(sys.argv)
    ~~~~~~~~~~~~~~~~~~~~~~~~~^^^^^^^^^^
  File "C:\Users\udayp\DatabaseStoreManager\nyvenv\Lib\site-packages\django\core\management\__init__.py", line 442, in execute_from_command_line
    utility.execute()
    ~~~~~~~~~~~~~~~^^
  File "C:\Users\udayp\DatabaseStoreManager\nyvenv\Lib\site-packages\django\core\management\__init__.py", line 436, in execute
    self.fetch_command(subcommand).run_from_argv(self.argv)
    ~~~~~~~~~~~~~~~~~~~~~~~~~~~~~~~~~~~~~~~~~~~~^^^^^^^^^^^
  File "C:\Users\udayp\DatabaseStoreManager\nyvenv\Lib\site-packages\django\core\management\base.py", line 416, in run_from_argv
    self.execute(*args, **cmd_options)
    ~~~~~~~~~~~~^^^^^^^^^^^^^^^^^^^^^^
  File "C:\Users\udayp\DatabaseStoreManager\nyvenv\Lib\site-packages\django\core\management\base.py", line 460, in execute
    output = self.handle(*args, **options)
  File "C:\Users\udayp\DatabaseStoreManager\nyvenv\Lib\site-packages\django\core\management\base.py", line 107, in wrapper
    res = handle_func(*args, **kwargs)
  File "C:\Users\udayp\DatabaseStoreManager\nyvenv\Lib\site-packages\django\core\management\commands\migrate.py", line 114, in handle
    executor = MigrationExecutor(connection, self.migration_progress_callback)
  File "C:\Users\udayp\DatabaseStoreManager\nyvenv\Lib\site-packages\django\db\migrations\executor.py", line 18, in __init__
    self.loader = MigrationLoader(self.connection)
                  ~~~~~~~~~~~~~~~^^^^^^^^^^^^^^^^^
  File "C:\Users\udayp\DatabaseStoreManager\nyvenv\Lib\site-packages\django\db\migrations\loader.py", line 58, in __init__
    self.build_graph()
    ~~~~~~~~~~~~~~~~^^
  File "C:\Users\udayp\DatabaseStoreManager\nyvenv\Lib\site-packages\django\db\migrations\loader.py", line 235, in build_graph
    self.applied_migrations = recorder.applied_migrations()
                              ~~~~~~~~~~~~~~~~~~~~~~~~~~~^^
  File "C:\Users\udayp\DatabaseStoreManager\nyvenv\Lib\site-packages\django\db\migrations\recorder.py", line 89, in applied_migrations
    if self.has_table():
       ~~~~~~~~~~~~~~^^
  File "C:\Users\udayp\DatabaseStoreManager\nyvenv\Lib\site-packages\django\db\migrations\recorder.py", line 63, in has_table
    with self.connection.cursor() as cursor:
         ~~~~~~~~~~~~~~~~~~~~~~^^
  File "C:\Users\udayp\DatabaseStoreManager\nyvenv\Lib\site-packages\django\utils\asyncio.py", line 26, in inner
    return func(*args, **kwargs)
  File "C:\Users\udayp\DatabaseStoreManager\nyvenv\Lib\site-packages\django\db\backends\base\base.py", line 320, in cursor
    return self._cursor()
           ~~~~~~~~~~~~^^
  File "C:\Users\udayp\DatabaseStoreManager\nyvenv\Lib\site-packages\django\db\backends\base\base.py", line 296, in _cursor
    self.ensure_connection()
    ~~~~~~~~~~~~~~~~~~~~~~^^
  File "C:\Users\udayp\DatabaseStoreManager\nyvenv\Lib\site-packages\django\utils\asyncio.py", line 26, in inner
    return func(*args, **kwargs)
  File "C:\Users\udayp\DatabaseStoreManager\nyvenv\Lib\site-packages\django\db\backends\base\base.py", line 279, in ensure_connection
    self.connect()
    ~~~~~~~~~~~~^^
  File "C:\Users\udayp\DatabaseStoreManager\nyvenv\Lib\site-packages\django\utils\asyncio.py", line 26, in inner
    return func(*args, **kwargs)
  File "C:\Users\udayp\DatabaseStoreManager\nyvenv\Lib\site-packages\django\db\backends\base\base.py", line 255, in connect
    conn_params = self.get_connection_params()
  File "C:\Users\udayp\DatabaseStoreManager\nyvenv\Lib\site-packages\django\db\backends\postgresql\base.py", line 241, in get_connection_params
    raise ImproperlyConfigured(
    ...<2 lines>...
    )
django.core.exceptions.ImproperlyConfigured: settings.DATABASES is improperly configured. Please supply the NAME or OPTIONS['service'] value.

(nyvenv) C:\Users\udayp\DatabaseStoreManager>